const f = () => {
  try {
    let a = 5;
    console.log(program);
    console.log("Program run sucessfully");
  } catch {
    console.log("This is an error");
    console.log(p);
  } finally {
    console.log("I am a good boy");
  }
};
f();
